Workbook

Sheet Итог
A1: ОПЕРАЦИОННЫЙ РЕЗЕРВ ПВЗ OZON — ОРСК, 15.10–25.12.2026
A2: Период резерва: 15.10.2026 — 25.12.2026 включительно (72 календарных дня). Консервативно: деньги Ozon до 25.12.2026 недоступны, октябрьская частичная выплата 25.11 неизвестна и не вычитается. Жёлтые ячейки — входные данные, белые — формулы.
A5: КЛЮЧЕВЫЕ ДАТЫ
A6: 46310 | B6: Оформление ПВЗ и начало расходов «на себя»
A7: 46330 | B7: Платёж по новому кредиту № 1 — 33 840 ₽
A8: 46351 | B8: Частичная выплата Ozon за октябрь — сумма НЕИЗВЕСТНА, в резерв не заложена
A9: 46360 | B9: Платёж по новому кредиту № 2 — 33 840 ₽
A10: 46381 | B10: Первая полная выплата Ozon (за ноябрь) — конец периода резерва
A11: 46387 | B11: Срок уплаты фиксированных взносов ИП за 2026 г. (при УСН) — дату уточнить
A13: 1. БИЗНЕС-РЕЗЕРВ ПВЗ (деньги бизнеса)
A14: Статья | B14: УСН 6% | C14: АУСН 8% | D14: Примечание
A15: Расходы ПВЗ за 72 дня (аренда, электричество, cashback, интернет, камеры, персонал, налоги и взносы) | B15: ='Расходы бизнеса'!D57 | C15: ='Расходы бизнеса'!E57 | D15: Детализация — лист «Расходы бизнеса»
A16: Платежи по новому кредиту (04.11 и 04.12 = 2 × 33 840 ₽) | B16: ='Кредит'!B19 | C16: ='Кредит'!B19 | D16: Кредит 923 000 ₽, 59 платежей — лист «Кредит»
A17: Дополнительный буфер (добавить один раз) | B17: ='Расходы бизнеса'!B9 | C17: ='Расходы бизнеса'!B9
A18: ИТОГО ОПЕРАЦИОННЫЙ РЕЗЕРВ | B18: =SUM(B15:B17) | C18: =SUM(C15:C17) | D18: БЕЗ цены покупки ПВЗ и личных расходов
A19: Осторожный вариант: 3 полных месяца расходов, cashback — за 72 факт. дня | B19: ='Расходы бизнеса'!D58+'Кредит'!B19+'Расходы бизнеса'!B9 | C19: ='Расходы бизнеса'!E58+'Кредит'!B19+'Расходы бизнеса'!B9 | D19: Если аренда/зарплаты/счета оплачиваются полными месячными суммами
A21: 2. ПОСТУПЛЕНИЯ OZON В ПЕРИОДЕ (в резерв консервативно не заложены)
A22: Полная выплата Ozon 25.12.2026 (за ноябрь) | B22: 0 | C22: 0 | D22: Первая полная выплата после передачи; день окончания резерва
A23: Частичная выплата Ozon 25.11.2026 | B23: 0 | C23: 0 | D23: Сумма неизвестна — не вычитается из резерва до подтверждения
A24: Грубая оценка октябрьской части (17/30 от Q3-среднего) | B24: ='Доходы Ozon'!B35 | D24: Только ориентир начисленного вознаграждения: не гарантия и не чистый доход
A25: Вознаграждение Ozon по скриншотам — начисления в кабинете, а НЕ подтверждённая чистая прибыль. Drop-off и «Выдача» уже входят в общее вознаграждение и в модели не добавляются повторно.
A27: 3. ЛИЧНЫЕ ПЛАТЕЖИ (отдельно от бизнеса)
A28: Аренда квартиры (20 000 ₽/мес × 2,4) | B28: ='Личные финансы'!C6
A29: Старый автокредит (16 500 ₽/мес × 2,4) | B29: ='Личные финансы'!C7
A30: Итого личные расходы за 72 дня | B30: =SUM(B28:B29)
A31: Зарплата на заводе (источник покрытия, ориентир 120 000 ₽/мес × 2,4) | B31: ='Личные финансы'!C11 | D31: Диапазон 264 000–312 000 ₽ за период (110–130 тыс./мес)
A32: Сальдо личного блока | B32: =B31-B30 | D32: Личное — отдельно от бизнеса; основную работу сохраняем
A34: 4. ЦЕНА ПОКУПКИ ПВЗ (отдельно, НЕ входит в операционный резерв)
A35: Диапазон оценки | B35: 650 000 — 700 000 ₽ | D35: Цена не согласована
A36: Расчётный ориентир | B36: 675000 | D36: Только ориентир для расчётов
A37: Кредит на рефинансирование (по документам) | B37: ='Кредит'!B5 | D37: 59 платежей по 33 840 ₽, последний 31 083,47 ₽
A38: Оценка свободных средств после закрытия долгов (143 323,53 + 50 000) | B38: ='Кредит'!B24 | D38: Подтвердить фактические суммы закрытия в банке; не считать все 923 000 ₽ свободными автоматически
A40: 5. ГЛАВНЫЕ ДОПУЩЕНИЯ (полный список — лист «Допущения и вопросы»)
A41: • Резерв рассчитан консервативно: поступления Ozon до 25.12.2026 не учитываются; октябрьская частичная выплата 25.11 неизвестна.
A42: • УСН 6% и АУСН 8% посчитаны на одной базе — Q3-среднем вознаграждении 241 507,06 ₽/мес (предварительная оценка, не подтверждённая налоговая база).
A43: • АУСН: тариф страховых взносов за сотрудников 0%, ИП освобождён от фиксированных взносов и 1% свыше 300 000 ₽ (ФЗ № 17-ФЗ); сохраняется фиксированный ВНиМ 2 959 ₽/год = 246,58 ₽/мес. Оренбургская область в эксперименте АУСН с 01.01.2025; режим экспериментальный (до 31.12.2027) — проверить условия: доход ≤ 60 млн ₽, сотрудников ≤ 5, уполномоченный банк, виды деятельности, запрет уходить с режима 12 месяцев.
A44: • УСН: уменьшение налога взносами ограничено 50% (7 245,20 ₽/мес); право включить в уменьшение взносы за сотрудников уточнить у бухгалтера (переключатель B11 на листе «Расходы бизнеса»).
A45: • «Прочие категории» вознаграждения (229 473,93 ₽ за 9 мес.), ставки взносов 30% и травматизма, даты фактической уплаты налогов — сверить с актами Ozon и бухгалтером.
A46: • Ориентир для планирования: около 600–650 тыс. ₽ резерва (перекрывает осторожный вариант по обоим режимам) без цены покупки ПВЗ, личных расходов и старого автокредита.
A47: • Оценка покупки второго ПВЗ (100–120 привозов/день) и ориентир его цены — отдельный лист «Второй ПВЗ (оценка)».

Sheet Доходы Ozon
A1: ВОЗНАГРАЖДЕНИЕ OZON ПО СКРИНШОТАМ ВЛАДЕЛЬЦА, 2026
A2: Это начисления в кабинете Ozon, а НЕ подтверждённая чистая прибыль и НЕ банковское поступление. Drop-off и «Выдача» уже входят в «Всего» — в модели они не прибавляются повторно. «Прочие категории» рассчитаны как разница и подлежат сверке с актами Ozon.
A4: Месяц | B4: Всего вознаграждение, ₽ | C4: Drop-off, ₽ | D4: Выдача, ₽ | E4: Прочие категории (разница), ₽ | F4: Прочие, %
A5: Январь | B5: 242509.97 | C5: 132317.5 | D5: 92010.07 | E5: =B5-C5-D5 | F5: =IF(B5=0,0,E5/B5)
A6: Февраль | B6: 225370.47 | C6: 117155 | D6: 92568.25 | E6: =B6-C6-D6 | F6: =IF(B6=0,0,E6/B6)
A7: Март | B7: 261274.78 | C7: 127570 | D7: 115251.88 | E7: =B7-C7-D7 | F7: =IF(B7=0,0,E7/B7)
A8: Апрель | B8: 270698.4 | C8: 145642.5 | D8: 101878.14 | E8: =B8-C8-D8 | F8: =IF(B8=0,0,E8/B8)
A9: Май | B9: 318913.63 | C9: 181365 | D9: 110366.03 | E9: =B9-C9-D9 | F9: =IF(B9=0,0,E9/B9)
A10: Июнь | B10: 251632.32 | C10: 114337.5 | D10: 106197.69 | E10: =B10-C10-D10 | F10: =IF(B10=0,0,E10/B10)
A11: Июль | B11: 222467.62 | C11: 66895 | D11: 122142.11 | E11: =B11-C11-D11 | F11: =IF(B11=0,0,E11/B11)
A12: Август | B12: 213911.06 | C12: 59477.5 | D12: 126040.26 | E12: =B12-C12-D12 | F12: =IF(B12=0,0,E12/B12)
A13: Сентябрь | B13: 288142.49 | C13: 107135 | D13: 147097.38 | E13: =B13-C13-D13 | F13: =IF(B13=0,0,E13/B13)
A14: Итого январь–сентябрь | B14: =SUM(B5:B13) | C14: =SUM(C5:C13) | D14: =SUM(D5:D13) | E14: =SUM(E5:E13) | F14: =E14/B14
A15: Среднее янв–сен, ₽/мес | B15: =B14/9
A16: Среднее июль–сентябрь (Q3), ₽/мес | B16: =AVERAGE(B11:B13)
A17: Drop-off Q3, среднее, ₽/мес | B17: =AVERAGE(C11:C13)
A18: Данные владельца: за август около 5 700 выдач, за сентябрь около 5 800 выдач. Точное соответствие «выдач» и ставок — сверить с актами Ozon.
A20: ПРОВЕРКА МОДЕЛЬНОГО ПОТОКА СЕЛЛЕРОВ
A21: Модель владельца: 250 товаров × 10 ₽ × 30 дней | B21: =250*10*30
A22: Фактический Drop-off Q3 (среднее по скриншотам) | B22: =B17
A23: Cashback селлерам (1 000 ₽/день, выплата еженедельная) | B23: 30000
A24: Модельный поток до налогов и прочих расходов | B24: =B21-B23
A25: 75 000 ₽/мес — это проверка Drop-off, а НЕ дополнительный доход сверх общего вознаграждения Ozon. Фактический Drop-off Q3 (~77 836 ₽/мес) близок к модели, но объёмы и тарифы нужно сверить. Cashback — один расход; не добавлять вторую такую же статью как «логистика/доставка».
A27: БАЗА ДЛЯ НАЛОГОВОЙ ОЦЕНКИ (предварительная, не подтверждённая)
A28: Q3-среднее — используется в модели | B28: =B16
A29: Альтернатива — среднее янв–сен | B29: =B15
A30: Налоговая база определяется фактическими начислениями за период работы с 15.10.2026 и правом на вычеты; в модели — модельная оценка на Q3-среднем.
A32: ВЫПЛАТЫ OZON В ПЕРИОДЕ РЕЗЕРВА
A33: Частичная выплата за 15–31.10 — ожидается 25.11.2026 | B33: 0 | C33: Сумма неизвестна — в резерв не заложена
A34: Полная выплата за ноябрь — 25.12.2026 | B34: 0 | C34: Первая полная выплата после передачи; день окончания резерва
A35: Грубая оценка октябрьской части (17/30 от Q3-среднего) | B35: =B16*17/30 | C35: Только ориентир: не гарантия и не чистый доход

Sheet Расходы бизнеса
A1: РАСХОДЫ БИЗНЕСА, ПЕРСОНАЛ, НАЛОГИ — 15.10–25.12.2026 (72 ДНЯ)
A2: Жёлтые ячейки — входные данные. Пропорция 72/30 = 2,4 условных месяца; денежные средства Ozon до 25.12.2026 считаются недоступными (октябрьская частичная выплата 25.11 неизвестна и не вычитается).
A4: ПАРАМЕТРЫ ПЕРИОДА
A5: Дата начала расходов «на себя» | B5: 46310
A6: Дата первой полной выплаты Ozon | B6: 46381
A7: Календарных дней в периоде | B7: =B6-B5+1
A8: Условных месяцев (дней / 30) | B8: =B7/30
A9: Дополнительный буфер (добавить один раз), ₽ | B9: 50000
A10: Cashback селлерам, ₽/день | B10: 1000
A11: Уменьшать УСН на взносы за сотрудников (1 = да, 0 = нет) | B11: 1 | F11: Уточнить право у бухгалтера: собственных взносов не хватает для лимита 50%
A12: Альт. ориентир взносов, ₽/мес на сотрудника (для проверки) | B12: 8100 | F12: Ранее встречавшийся ориентир 8 100 ₽ на сотрудника — см. проверку ниже
A14: 1. РЕГУЛЯРНЫЕ РАСХОДЫ (без персонала)
A15: Статья | B15: ₽/мес (30 дн) | C15: ₽ за 72 дня | F15: Примечание
A16: Аренда помещения ПВЗ | B16: 42000 | C16: =B16*$B$8 | F16: Даты платежей аренды уточнить: может требоваться полный месяц
A17: Электричество | B17: 3000 | C17: =B17*$B$8 | F17: «До 3 000 ₽» — в расчёте 3 000 ₽
A18: Cashback селлерам | B18: =$B$10*30 | C18: =$B$10*$B$7 | F18: 1 000 ₽/день, выплата еженедельная; за 72 дня — 72 000 ₽. Один расход, не дублировать
A19: Интернет | B19: 1800 | C19: =B19*$B$8
A20: Камеры | B20: 2100 | C20: =B20*$B$8
A21: Прочие траты (ремонт, расходники, бухгалтерия и т. п.) | B21: 0 | C21: =B21*$B$8 | F21: Владельцем не подтверждены — редактируемая строка, по умолчанию 0
A22: Итого регулярные расходы | B22: =SUM(B16:B21) | C22: =SUM(C16:C21)
A24: 2. ПЕРСОНАЛ (2 сотрудника, оформлены официально)
A25: Статья | B25: ₽/мес | C25: ₽ за 72 дня | F25: Примечание
A26: Сотрудников, чел. | B26: 2
A27: Зарплата на руки на человека, ₽/мес | B27: 27000 | F27: 2 000 ₽ за смену уже включены в 27 000 ₽ — отдельно не прибавляем
A28: ФОТ на руки всего | B28: =B26*B27
A29: Gross ФОТ (с НДФЛ 13%) | B29: =B28/(1-0.13)
A30: НДФЛ 13% (удерживается из gross) | B30: =B29-B28 | F30: Уже внутри gross — не добавляем к расходам второй раз
A31: Страховые взносы работодателя 30% | B31: =B29*0.3 | F31: Ставку подтвердить у бухгалтера; на АУСН тариф 0% (см. ниже)
A32: Травматизм сотрудников (300 ₽/чел.) | B32: =B26*300 | F32: Ориентир — подтвердить класс профриска; на АУСН — фиксированный ВНиМ ниже
A33: Итого полная стоимость ФОТ (УСН) | B33: =B29+B31+B32 | C33: =B33*$B$8
A34: Персонал на АУСН (только gross) | B34: =B29 | C34: =B34*$B$8 | F34: На АУСН страховые взносы за сотрудников 0% (ч. 1 ст. 18 ФЗ № 17-ФЗ)
A35: Незарегистрированных сотрудников в модели нет: оба сотрудника оформлены официально, НДФЛ удерживается из gross.
A36: 3. НАЛОГИ И ВЗНОСЫ — СРАВНЕНИЕ РЕЖИМОВ
A37: Статья | B37: УСН 6% | C37: АУСН 8% | F37: Примечание
A38: Налоговая база (модель), ₽/мес | B38: ='Доходы Ozon'!B28 | C38: ='Доходы Ozon'!B28 | F38: Q3-среднее вознаграждения; предварительная оценка, не подтверждённая база
A39: Ставка налога | B39: 0.06 | C39: 0.08
A40: Налог до уменьшения | B40: =B38*B39 | C40: =C38*C39
A41: Собственные взносы ИП — фиксированные (57 390 ₽/год) | B41: 4782.5 | C41: 0 | F41: На АУСН ИП освобождён от фиксированных взносов «за себя»
A42: Собственные взносы ИП — 1% свыше 300 000 ₽/год | B42: 2165.07 | C42: 0 | F42: (2 898 085 − 300 000) × 1% / 12; на АУСН 1% не платится
A43: Взносы за сотрудников (30% + травматизм) | B43: =B31+B32 | C43: 0 | F43: На АУСН тариф 0% (ч. 1 ст. 18 ФЗ № 17-ФЗ) — взносов за персонал нет
...

Sheet Таблица владельца
A1: ТАБЛИЦА ДЕНЕЖНЫХ ПОТОКОВ ПВЗ (воссоздана по фото модели владельца)
A2: Колонки — полумесячные периоды, дата в шапке = КОНЕЦ периода (30.окт = 15.10–30.10 и т. д.). Жёлтые ячейки — значения для редактирования, остальное — формулы. Выплаты Ozon: 25.11 — 110 000 ₽ (октябрь, частичная), 25.12 — 230 000 ₽, 25.01 — 240 000 ₽, 25.02 — 225 000 ₽.
A4: Статья | B4: 15.окт | C4: 30.окт | D4: 15.ноя | E4: 30.ноя | F4: 15.дек | G4: 30.дек | H4: 15.янв | I4: 30.янв | J4: 15.фев | K4: 28.фев | L4: Итого за период | N4: РАСЧЕТ ДО 30 ДЕКАБРЯ (2,5 мес.)
A5: Аренда | C5: 42000 | E5: 42000 | G5: 42000 | I5: 42000 | K5: 42000 | L5: =SUM(B5:K5) | N5: Аренда (3 платежа) | O5: =C5*3
A6: Электричество | C6: 3000 | E6: 3000 | G6: 3000 | I6: 3000 | K6: 3000 | L6: =SUM(B6:K6) | N6: Электричество (3 мес.) | O6: =C6*3
A7: Селлер (cashback) | C7: 15000 | D7: 15000 | E7: 15000 | F7: 15000 | G7: 15000 | H7: 15000 | I7: 15000 | J7: 15000 | K7: 15000 | L7: =SUM(B7:K7) | N7: Селлер / cashback (5 полумесяцев) | O7: =C7*5
A8: Камеры | C8: 2100 | E8: 2100 | G8: 2100 | I8: 2100 | K8: 2100 | L8: =SUM(B8:K8) | N8: Камеры (3 мес.) | O8: =C8*3
A9: Интернет | C9: 1800 | E9: 1800 | G9: 1800 | I9: 1800 | K9: 1800 | L9: =SUM(B9:K9) | N9: Интернет (3 мес.) | O9: =C9*3
A10: Кредит | D10: 34000 | F10: 34000 | H10: 34000 | J10: 34000 | L10: =SUM(B10:K10) | N10: Кредит (3 платежа по 34 000) | O10: =D10*3
A11: Зарплата (зп) | C11: 35000 | D11: 35000 | E11: 35000 | F11: 35000 | G11: 35000 | H11: 35000 | I11: 35000 | J11: 35000 | K11: 35000 | L11: =SUM(B11:K11) | N11: Зарплата (5 полумесяцев) | O11: =C11*5
A12: Разовые траты старта (состав уточнить) | C12: 30300 | L12: =SUM(B12:K12) | N12: ИТОГО РАСХОДОВ до 30 декабря | O12: =SUM(O5:O11)
A13: ИТОГО расходов за период | B13: =SUM(B5:B12) | C13: =SUM(C5:C12) | D13: =SUM(D5:D12) | E13: =SUM(E5:E12) | F13: =SUM(F5:F12) | G13: =SUM(G5:G12) | H13: =SUM(H5:H12) | I13: =SUM(I5:I12) | ... K13: =SUM(K5:K12) | L13: =SUM(B13:K13)
A14: ИТОГО за месяц (два полумесяца) | C14: =B13+C13 | E14: =D13+E13 | G14: =F13+G13 | I14: =H13+I13 | K14: =J13+K13 | N14: Выплата 25.12 (за ноябрь) | O14: =G18
A15: Первый период (30.окт) = 129 200 ₽: обычные расходы полумесяца 98 900 ₽ + разовые траты старта 30 300 ₽ (взяты из модели владельца — состав подтвердить). Полный месяц = 182 900 ₽ (42 000 + 3 000 + 30 000 + 2 100 + 1 800 + 34 000 + 70 000). | N15: минус налог 7% | O15: =G18-G20
N16: ЕСЛИ ИСПОЛЬЗОВАТЬ ВЫПЛАТУ ЗА ДЕКАБРЬ | O16: =O12-G20
A17: ВЫПЛАТЫ OZON, НАЛОГ И ОСТАТОК
A18: Выплата Ozon (дата в периоде) | E18: 110000 | G18: 230000 | I18: 240000 | K18: 225000 | L18: =SUM(B18:K18) | N18: Блок воспроизводит расчёт владельца: месячные статьи — 3 платежа, полумесячные (селлер, зп) — 5.
A19: Налог 7% от выплаты (модель владельца) | E19: =E18*0.07 | G19: =G18*0.07 | I19: =I18*0.07 | K19: =K18*0.07 | L19: =SUM(B19:K19) | N19: Кредит: фактически до 25.12 платежи 04.11 и 04.12 = 2 × 33 840 = 67 680 ₽; в блоке — 3 платежа (осторожно).
A20: Выплата минус налог | B20: =IF(B18=0,0,B18-B19) | C20: =IF(C18=0,0,C18-C19) | D20: =IF(D18=0,0,D18-D19) | E20: =IF(E18=0,0,E18-E19) | F20: =IF(F18=0,0,F18-F19) | G20: =IF(G18=0,0,G18-G19) | H20: =IF(H18=0,0,H18-H19) | I20: =IF(I18=0,0,I18-I19) | ... K20: =IF(K18=0,0,K18-K19) | L20: =SUM(B20:K20) | N20: Налог 7% от выплаты — упрощение модели владельца; подробно УСН/АУСН — на листе «Расходы бизнеса».
A21: ОСТАТОК за месяц (как в модели владельца) | C21: =C20-C14 | E21: =E20-E14 | G21: =G20-G14 | I21: =I20-I14 | K21: =K20-K14
A22: Накопительный остаток (доп. строка) | B22: =SUM($B$20:B20)-SUM($B$13:B13) | C22: =SUM($B$20:C20)-SUM($B$13:C13) | D22: =SUM($B$20:D20)-SUM($B$13:D13) | E22: =SUM($B$20:E20)-SUM($B$13:E13) | F22: =SUM($B$20:F20)-SUM($B$13:F13) | G22: =SUM($B$20:G20)-SUM($B$13:G13) | H22: =SUM($B$20:H20)-SUM($B$13:H13) | I22: =SUM($B$20:I20)-SUM($B$13:I13) | ... K22: =SUM($B$20:K20)-SUM($B$13:K13)
A23: «Остаток за месяц» = выплата минус налог минус расходы месяца. «Накопительный остаток» — реальное сальдо бизнеса с нуля: к 28.02 оно составляет около −112 150 ₽, то есть при заданном графике выплат бизнесу нужно примерно 112 тыс. ₽ своих денег на весь период; консервативный резерв до 25.12 (без учёта выплат) — на листе «Итог».

Sheet Кредит
A1: КРЕДИТ НА РЕФИНАНСИРОВАНИЕ (по документам банка)
A2: В прежнем сообщении называлась сумма ~950 000 ₽; в документах банка — 923 000 ₽. Ниже — параметры из графиков банка.
A4: ПАРАМЕТРЫ
A5: Сумма кредита, ₽ | B5: 923000
A6: Количество платежей | B6: 59
A7: Регулярный платёж, ₽ | B7: 33840
A8: Последний платёж, ₽ | B8: 31083.47
A9: Дата первого платежа | B9: 46330 | D9: Далее — 4-го числа ежемесячно
A10: Ставка по графику, % годовых | B10: 0.365
A11: ПСК, % | B11: 0.36481
A12: Реальная переплата (из графика банка), % годовых | B12: 0.2359
A13: Штраф за просрочку, % в день | B13: 0.001
A14: Ставка при невыполнении цели рефинансирования, % | B14: 0.565 | D14: Базовый диапазон 21,9–39,9% + надбавка 20 п. п.
A16: ПЛАТЕЖИ В ПЕРИОДЕ РЕЗЕРВА 15.10–25.12.2026
A17: 04.11.2026 — платёж 1 | B17: =$B$7
A18: 04.12.2026 — платёж 2 | B18: =$B$7
A19: Итого платежей до выплаты 25.12.2026 | B19: =SUM(B17:B18)
A21: РЕФИНАНСИРОВАНИЕ — СВОБОДНЫЕ СРЕДСТВА
A22: Остаток долга № 1 (из документов), ₽ | B22: 143323.53
A23: Остаток долга № 2 (из документов), ₽ | B23: 50000
A24: Оценка свободных средств после закрытия долгов, ₽ | B24: =B5-B22-B23
A25: Фактические суммы закрытия долгов и реально свободные деньги (с учётом возможных комиссий, страхования, порядка зачисления) необходимо подтвердить в банке. Не считать автоматически все 923 000 ₽ свободными на покупку ПВЗ.
A26: Старый автокредит 16 500 ₽/мес, возможно, является одним из рефинансируемых долгов — не учитывать старый и новый платёж одновременно без подтверждения состава рефинансирования.
A28: ГРАФИК ПЛАТЕЖЕЙ (59 платежей)
A29: № | B29: Дата | C29: Платёж, ₽ | D29: В периоде резерва?
A30: 1 | B30: 46330 | C30: 33840 | D30: да
A31: 2 | B31: 46360 | C31: 33840 | D31: да
A32: 3 | B32: 46391 | C32: 33840 | D32: нет
A33: 4 | B33: 46422 | C33: 33840 | D33: нет
A34: 5 | B34: 46450 | C34: 33840 | D34: нет
A35: 6 | B35: 46481 | C35: 33840 | D35: нет
A36: 7 | B36: 46511 | C36: 33840 | D36: нет
A37: 8 | B37: 46542 | C37: 33840 | D37: нет
A38: 9 | B38: 46572 | C38: 33840 | D38: нет
A39: 10 | B39: 46603 | C39: 33840 | D39: нет
A40: 11 | B40: 46634 | C40: 33840 | D40: нет
A41: 12 | B41: 46664 | C41: 33840 | D41: нет
... A88: 59 | B88: 48095 | C88: 31083.47 | D88: нет
A89: Всего выплат по графику, ₽ | C89: =SUM(C30:C88)
A90: В т. ч. проценты, ₽ | C90: =C89-B5
...

Sheet Личные финансы
A1: ЛИЧНЫЕ ПЛАТЕЖИ (ОТДЕЛЬНО ОТ БИЗНЕСА) — 15.10–25.12.2026
A2: Личный блок показан отдельно: средства бизнес-резерва на личные расходы не планируются. Основную работу на заводе сохраняем.
A4: ЛИЧНЫЕ РАСХОДЫ
A5: Статья | B5: ₽/мес | C5: ₽ за 72 дня | D5: Примечание
A6: Аренда квартиры | B6: 20000 | C6: =B6*'Расходы бизнеса'!$B$8
A7: Старый автокредит | B7: 16500 | C7: =B7*'Расходы бизнеса'!$B$8 | D7: Может быть рефинансирован — тогда платёж внутри нового кредита
A8: Итого личные расходы | B8: =SUM(B6:B7) | C8: =SUM(C6:C7)
A10: ИСТОЧНИК ПОКРЫТИЯ — ЗАРПЛАТА НА ЗАВОДЕ
A11: Зарплата (ориентир 120 000 ₽/мес) | B11: 120000 | C11: =B11*'Расходы бизнеса'!$B$8
A12: Минимум (110 000 ₽/мес) | B12: 110000 | C12: =B12*'Расходы бизнеса'!$B$8
A13: Максимум (130 000 ₽/мес) | B13: 130000 | C13: =B13*'Расходы бизнеса'!$B$8
A15: Сальдо личного блока (зарплата − личные расходы) | C15: =C11-C8 | D15: Личные расходы покрыты зарплатой завода; при этом основную работу сохраняем
A17: Если старый автокредит будет рефинансирован в новый кредит, его платёж 16 500 ₽/мес исчезнет из личного блока, а сумма долга войдёт в 923 000 ₽ — не учитывать дважды.

Sheet Второй ПВЗ (оценка)
A1: ОЦЕНКА ВТОРОГО ПВЗ (привоз 100–120 товаров/день)
A2: Расчёт — экстраполяция экономики вашего ПВЗ на меньший объём: ставки и структура расходов взяты из ваших данных, объём и часть статей расходов масштабируются. Жёлтые ячейки — ввод. Это модель для переговоров, не факт: реальные цифры берутся из кабинета Ozon владельца точки.
A4: 1. ОБЪЁМ И ВОЗНАГРАЖДЕНИЕ (масштаб от вашего ПВЗ)
A5: Показатель | B5: Значение | F5: Примечание
A6: Привоз, товаров/день | B6: 110 | F6: У вашего ПВЗ ~250/день; у рассматриваемой точки 100–120
A7: Тариф drop-off, ₽/товар | B7: 10 | F7: Ваша модель: 250 × 10 ₽ × 30 = 75 000 ₽; факт Q3 = 77 836 ₽ (≈10,4 ₽/товар)
A8: Выдач на 1 привезённый товар | B8: 0.77 | F8: У вас: ~5 700–5 800 выдач при ~7 500 привозов в месяц
A9: Тариф выдачи, ₽ за выдачу | B9: 22.91 | F9: Факт Q3: 131 760 ₽ / 5 750 выдач
A10: Drop-off, ₽/мес | B10: =B6*30*B7
A11: Выдач, шт/мес | B11: =B6*30*B8
A12: Выдача, ₽/мес | B12: =B11*B9
A13: Прочие категории, ₽/мес | B13: =B6/250*31911.31 | F13: Пропорционально объёму (Q3 у вас: 31 911 ₽/мес; сверить с актами)
A14: ВОЗНАГРАЖДЕНИЕ, ₽/мес | B14: =B10+B12+B13 | F14: Проверка: 241 507 ₽ × (110/250) ≈ 106 263 ₽
A16: 2. РАСХОДЫ ТОЧКИ (ввод)
A17: Аренда, ₽/мес | B17: 30000 | F17: У вас 42 000; у маленькой точки обычно меньше — уточнить по договору
A18: Электричество, ₽/мес | B18: 2500
A19: Интернет, ₽/мес | B19: 1800
A20: Камеры, ₽/мес | B20: 2100
A21: Cashback селлерам, ₽/мес | B21: =B6/250*1000*30 | F21: Масштабируется от объёма: 1 000 ₽/день у вас при 250 привозов (здесь 440 ₽/день × 30)
A22: Сотрудников, чел. | B22: 1 | F22: Ключевой параметр: при 100–120 привозов/день точка тянет одного сотрудника
A23: Зарплата на руки, ₽/мес на человека | B23: 27000
A25: 3. ПЕРСОНАЛ
A26: Gross ФОТ (с НДФЛ 13%) | B26: =B22*B23/(1-0.13)
A27: Страховые взносы 30% | B27: =B26*0.3
A28: Травматизм (300 ₽/чел.) | B28: =B22*300
A29: Полная стоимость ФОТ (УСН) | B29: =B26+B27+B28
A30: Персонал на АУСН (только gross) | B30: =B26 | F30: На АУСН взносы за сотрудников 0% — для маленькой точки это решающая экономия
A32: 4. НАЛОГИ И ВЗНОСЫ ИП (точка отдельным ИП)
B33: АУСН 8% | C33: УСН 6% | F33: Примечание
A34: Ставка налога | B34: 0.08 | C34: 0.06
A35: Налог до уменьшения | B35: =$B$14*B34 | C35: =$B$14*C34
A36: Уменьшение налога взносами (≤50%) | C36: =MIN(4782.5+($B$14*12-300000)*0.01/12+B27+B28,C35*0.5) | F36: Свои взносы (4 782,50 + 1%) + взносы за сотрудника; лимит 50%
A37: ВНиМ ИП (АУСН, 2 959 ₽/год) | B37: 246.58 | C37: 0
A38: Итого налоги и взносы ИП, ₽/мес | B38: =B35+B37 | C38: =C35-C36+4782.5+($B$14*12-300000)*0.01/12 | F38: УСН: налог после уменьшения + фиксвзносы 4 782,50 + 1% свыше 300 000 ₽
A40: 5. ИТОГО: ПРИБЫЛЬ ТОЧКИ ПРИ РАЗНЫХ УСЛОВИЯХ
A41: Показатель | B41: АУСН, 1 сотрудник | C41: УСН, 1 сотрудник | D41: АУСН, 2 сотрудника | E41: УСН, 2 сотрудника
A42: Постоянные расходы (аренда, камеры, интернет, свет, cashback) | B42: =SUM(B17:B21) | C42: =SUM(B17:B21) | D42: =SUM(B17:B21) | E42: =SUM(B17:B21)
A43: Персонал | B43: =B30 | C43: =B29 | D43: =B30/B22*2 | E43: =B29/B22*2
A44: Налоги и взносы ИП | B44: =B38 | C44: =C38 | D44: =B38 | E44: =C38
A45: ИТОГО расходов, ₽/мес | B45: =B42+B43+B44 | C45: =C42+C43+C44 | D45: =D42+D43+D44 | E45: =E42+E43+E44
...

Sheet Допущения и вопросы
A1: ДОПУЩЕНИЯ, НЕИЗВЕСТНЫЕ СУММЫ И ВОПРОСЫ ДЛЯ ПРОВЕРКИ
A2: Модель построена на данных владельца (скриншоты вознаграждения Ozon за янв–сен 2026, вводные по расходам, документам банка). Все суммы — ориентировочные модельные начисления, не подтверждённые фактические платежи и не налоговая консультация.
A4: 1 | B4: Вознаграждение Ozon по скриншотам — начисления в кабинете, НЕ подтверждённая чистая прибыль и НЕ банковское поступление. Drop-off и «Выдача» уже входят в «Всего» и в модели не прибавляются повторно.
A5: 2 | B5: «Прочие категории» (229 473,93 ₽ за 9 мес.) рассчитаны как разница — сверить с актами Ozon.
A6: 3 | B6: Налоговая база — модельная: Q3-среднее 241 507,06 ₽/мес (альтернатива — среднее янв–сен 254 991,19 ₽/мес). Фактическая база зависит от начислений за период работы с 15.10.2026.
A7: 4 | B7: УСН 6%: уменьшение налога страховыми взносами ограничено 50% (7 245,20 ₽/мес). Собственных взносов ИП (6 947,57 ₽/мес) не хватает для полного уменьшения — в модели взносы за сотрудников включены в уменьшение (переключатель B11). Право на такое уменьшение уточнить у бухгалтера; без него налог 7 542,83 ₽/мес, резерв +714 ₽.
A8: 5 | B8: Ставка страховых взносов 30% и травматизм 300 ₽/чел./мес — ориентиры (ранее встречался ориентир 8 100 ₽ на сотрудника). Подтвердить у бухгалтера; на листе «Расходы бизнеса» есть проверка чувствительности.
A9: 6 | B9: АУСН 8% (по открытым источникам 2026 г.): тариф страховых взносов за сотрудников 0% (ч. 1 ст. 18 ФЗ № 17-ФЗ); ИП освобождён от фиксированных взносов «за себя» (57 390 ₽/год) и от 1% свыше 300 000 ₽; сохраняется фиксированный ВНиМ 2 959 ₽/год = 246,58 ₽/мес (платится только при наличии сотрудников). Уменьшения налога взносами на АУСН нет.
A10: 7 | B10: АУСН — экспериментальный режим (действует до 31.12.2027). Оренбургская область присоединилась с 01.01.2025 (Закон Оренбургской области от 29.11.2024 № 1292/547-VII-ОЗ). Проверить: лимит дохода ≤ 60 млн ₽/год, число сотрудников ≤ 5, расчёты через уполномоченный банк, допустимость вида деятельности/схемы с Ozon, невозможность добровольно уйти с режима в течение 12 месяцев.
A11: 8 | B11: Даты фактической уплаты налогов и взносов уточнить (фиксированные взносы ИП — до 31.12.2026); в модели — помесячный эквивалент.
A12: 9 | B12: Октябрьская частичная выплата 25.11.2026 — сумма неизвестна, в резерв не заложена. Грубая оценка 136 853,81 ₽ (17/30 от Q3-среднего) — только ориентир: не гарантия и не чистый доход.
A13: 10 | B13: Cashback 1 000 ₽/день (72 000 ₽ за период) — один расход; не дублировать как отдельную логистику/доставку.
A14: 11 | B14: Прочие траты (ремонт, расходники, бухгалтерия и т. п.) владельцем не подтверждены — редактируемая строка на листе «Расходы бизнеса», по умолчанию 0 ₽.
A15: 12 | B15: Аренда, зарплаты и счета могут требовать оплаты полными месячными суммами — уточнить даты платежей; для этого в модели есть «осторожный вариант» (3 полных месяца).
... A19: 16 | B19: Drop-off: модель 250 товаров × 10 ₽ × 30 дней = 75 000 ₽/мес против фактических 77 835,83 ₽/мес за Q3 — сверить объёмы и тарифы; за август ~5 700 выдач, за сентябрь ~5 800.
A21: ИСТОЧНИКИ (проверка режима АУСН и параметров 2026 г.)
A22: 1 | B22: АУСН: 0% ставка страховых взносов, освобождение ИП от фиксированных взносов и 1% — https://www.v2b.ru/articles/strahovye-vznosy-i-ndfl-na-ausn-v-2026-godu/ ; https://www.klerk.ru/blogs/astral/634402/
A23: 2 | B23: ВНиМ на АУСН 2 959 ₽/год = 246,58 ₽/мес (2026) — https://www.moedelo.org/club/article-knowledge/vznosy-na-travmatizm-na-ausn-kak-platit-i-cto-delat-esli-net-rabotnikov
A24: 3 | B24: Оренбургская область в эксперименте АУСН с 01.01.2025 — https://vkirove.ru/news/2025/12/12/v_kakikh_regionakh_rf_deystvuet_ausn_v_2026_godu.html
A25: 4 | B25: Условия АУСН (доход ≤ 60 млн ₽, сотрудников ≤ 5, уполномоченный банк) — https://pay.yandex.ru/blog/articles/kak-rabotat-na-ausn-v-2026-godu
A26: 5 | B26: Фиксированные взносы ИП 2026 = 57 390 ₽, 1% свыше 300 000 ₽ — https://www.moedelo.org/club/article-knowledge/ip-i-strahovye-vznosy-v-2026-godu-skolko-platit-cto-izmenilos-i-kak-ne-pereplatit ; https://www.klerk.ru/blogs/moedelo/663649/
